<?xml version="1.0"?>
<!--
Simple Humanoid URDF Model
Physical AI & Humanoid Robotics Course - Module 1

A basic 10-joint humanoid robot model for ROS 2 visualization and simulation.

Structure:
- Torso (base_link)
- Head (1 DOF - neck rotation)
- Arms (2 DOF each - shoulder, elbow)
- Legs (2 DOF each - hip, knee)

Visualize with:
    ros2 launch urdf_tutorial display.launch.py model:=simple_humanoid.urdf

Or manually:
    ros2 run robot_state_publisher robot_state_publisher simple_humanoid.urdf
    ros2 run joint_state_publisher_gui joint_state_publisher_gui
    rviz2
-->

<robot name="simple_humanoid">

  <!-- ============ TORSO (Base Link) ============ -->
  <link name="base_link">
    <visual>
      <geometry>
        <box size="0.3 0.2 0.5"/>
      </geometry>
      <material name="blue">
        <color rgba="0.2 0.4 0.8 1.0"/>
      </material>
    </visual>
    <collision>
      <geometry>
        <box size="0.3 0.2 0.5"/>
      </geometry>
    </collision>
    <inertial>
      <mass value="10.0"/>
      <origin xyz="0 0 0"/>
      <inertia ixx="0.4" ixy="0.0" ixz="0.0"
               iyy="0.5" iyz="0.0"
               izz="0.2"/>
    </inertial>
  </link>

  <!-- ============ HEAD ============ -->
  <joint name="neck_joint" type="revolute">
    <parent link="base_link"/>
    <child link="head"/>
    <origin xyz="0 0 0.3" rpy="0 0 0"/>
    <axis xyz="0 0 1"/>
    <limit lower="-1.57" upper="1.57" effort="10.0" velocity="1.0"/>
    <dynamics damping="0.1" friction="0.1"/>
  </joint>

  <link name="head">
    <visual>
      <geometry>
        <sphere radius="0.12"/>
      </geometry>
      <material name="skin">
        <color rgba="1.0 0.8 0.6 1.0"/>
      </material>
    </visual>
    <collision>
      <geometry>
        <sphere radius="0.12"/>
      </geometry>
    </collision>
    <inertial>
      <mass value="2.0"/>
      <inertia ixx="0.01" ixy="0.0" ixz="0.0"
               iyy="0.01" iyz="0.0"
               izz="0.01"/>
    </inertial>
  </link>

  <!-- ============ RIGHT ARM ============ -->
  <!-- Right Shoulder -->
  <joint name="right_shoulder_joint" type="revolute">
    <parent link="base_link"/>
    <child link="right_upper_arm"/>
    <origin xyz="-0.18 0 0.2" rpy="0 0 0"/>
    <axis xyz="1 0 0"/>
    <limit lower="-3.14" upper="3.14" effort="20.0" velocity="2.0"/>
    <dynamics damping="0.2" friction="0.1"/>
  </joint>

  <link name="right_upper_arm">
    <visual>
      <origin xyz="0 0 -0.15" rpy="0 0 0"/>
      <geometry>
        <cylinder radius="0.04" length="0.3"/>
      </geometry>
      <material name="blue"/>
    </visual>
    <collision>
      <origin xyz="0 0 -0.15" rpy="0 0 0"/>
      <geometry>
        <cylinder radius="0.04" length="0.3"/>
      </geometry>
    </collision>
    <inertial>
      <mass value="1.5"/>
      <origin xyz="0 0 -0.15"/>
      <inertia ixx="0.015" ixy="0.0" ixz="0.0"
               iyy="0.015" iyz="0.0"
               izz="0.002"/>
    </inertial>
  </link>

  <!-- Right Elbow -->
  <joint name="right_elbow_joint" type="revolute">
    <parent link="right_upper_arm"/>
    <child link="right_lower_arm"/>
    <origin xyz="0 0 -0.3" rpy="0 0 0"/>
    <axis xyz="1 0 0"/>
    <limit lower="0.0" upper="2.8" effort="15.0" velocity="2.0"/>
    <dynamics damping="0.2" friction="0.1"/>
  </joint>

  <link name="right_lower_arm">
    <visual>
      <origin xyz="0 0 -0.125" rpy="0 0 0"/>
      <geometry>
        <cylinder radius="0.03" length="0.25"/>
      </geometry>
      <material name="skin"/>
    </visual>
    <collision>
      <origin xyz="0 0 -0.125" rpy="0 0 0"/>
      <geometry>
        <cylinder radius="0.03" length="0.25"/>
      </geometry>
    </collision>
    <inertial>
      <mass value="1.0"/>
      <origin xyz="0 0 -0.125"/>
      <inertia ixx="0.008" ixy="0.0" ixz="0.0"
               iyy="0.008" iyz="0.0"
               izz="0.001"/>
    </inertial>
  </link>

  <!-- ============ LEFT ARM ============ -->
  <!-- Left Shoulder -->
  <joint name="left_shoulder_joint" type="revolute">
    <parent link="base_link"/>
    <child link="left_upper_arm"/>
    <origin xyz="0.18 0 0.2" rpy="0 0 0"/>
    <axis xyz="1 0 0"/>
    <limit lower="-3.14" upper="3.14" effort="20.0" velocity="2.0"/>
    <dynamics damping="0.2" friction="0.1"/>
  </joint>

  <link name="left_upper_arm">
    <visual>
      <origin xyz="0 0 -0.15" rpy="0 0 0"/>
      <geometry>
        <cylinder radius="0.04" length="0.3"/>
      </geometry>
      <material name="blue"/>
    </visual>
    <collision>
      <origin xyz="0 0 -0.15" rpy="0 0 0"/>
      <geometry>
        <cylinder radius="0.04" length="0.3"/>
      </geometry>
    </collision>
    <inertial>
      <mass value="1.5"/>
      <origin xyz="0 0 -0.15"/>
      <inertia ixx="0.015" ixy="0.0" ixz="0.0"
               iyy="0.015" iyz="0.0"
               izz="0.002"/>
    </inertial>
  </link>

  <!-- Left Elbow -->
  <joint name="left_elbow_joint" type="revolute">
    <parent link="left_upper_arm"/>
    <child link="left_lower_arm"/>
    <origin xyz="0 0 -0.3" rpy="0 0 0"/>
    <axis xyz="1 0 0"/>
    <limit lower="0.0" upper="2.8" effort="15.0" velocity="2.0"/>
    <dynamics damping="0.2" friction="0.1"/>
  </joint>

  <link name="left_lower_arm">
    <visual>
      <origin xyz="0 0 -0.125" rpy="0 0 0"/>
      <geometry>
        <cylinder radius="0.03" length="0.25"/>
      </geometry>
      <material name="skin"/>
    </visual>
    <collision>
      <origin xyz="0 0 -0.125" rpy="0 0 0"/>
      <geometry>
        <cylinder radius="0.03" length="0.25"/>
      </geometry>
    </collision>
    <inertial>
      <mass value="1.0"/>
      <origin xyz="0 0 -0.125"/>
      <inertial ixx="0.008" ixy="0.0" ixz="0.0"
               iyy="0.008" iyz="0.0"
               izz="0.001"/>
    </inertial>
  </link>

  <!-- ============ RIGHT LEG ============ -->
  <!-- Right Hip -->
  <joint name="right_hip_joint" type="revolute">
    <parent link="base_link"/>
    <child link="right_thigh"/>
    <origin xyz="-0.1 0 -0.25" rpy="0 0 0"/>
    <axis xyz="1 0 0"/>
    <limit lower="-1.57" upper="1.57" effort="30.0" velocity="2.0"/>
    <dynamics damping="0.3" friction="0.2"/>
  </joint>

  <link name="right_thigh">
    <visual>
      <origin xyz="0 0 -0.2" rpy="0 0 0"/>
      <geometry>
        <cylinder radius="0.06" length="0.4"/>
      </geometry>
      <material name="blue"/>
    </visual>
    <collision>
      <origin xyz="0 0 -0.2" rpy="0 0 0"/>
      <geometry>
        <cylinder radius="0.06" length="0.4"/>
      </geometry>
    </collision>
    <inertial>
      <mass value="3.0"/>
      <origin xyz="0 0 -0.2"/>
      <inertia ixx="0.05" ixy="0.0" ixz="0.0"
               iyy="0.05" iyz="0.0"
               izz="0.01"/>
    </inertial>
  </link>

  <!-- Right Knee -->
  <joint name="right_knee_joint" type="revolute">
    <parent link="right_thigh"/>
    <child link="right_shin"/>
    <origin xyz="0 0 -0.4" rpy="0 0 0"/>
    <axis xyz="1 0 0"/>
    <limit lower="-2.5" upper="0.0" effort="25.0" velocity="2.0"/>
    <dynamics damping="0.3" friction="0.2"/>
  </joint>

  <link name="right_shin">
    <visual>
      <origin xyz="0 0 -0.175" rpy="0 0 0"/>
      <geometry>
        <cylinder radius="0.05" length="0.35"/>
      </geometry>
      <material name="skin"/>
    </visual>
    <collision>
      <origin xyz="0 0 -0.175" rpy="0 0 0"/>
      <geometry>
        <cylinder radius="0.05" length="0.35"/>
      </geometry>
    </collision>
    <inertial>
      <mass value="2.0"/>
      <origin xyz="0 0 -0.175"/>
      <inertia ixx="0.025" ixy="0.0" ixz="0.0"
               iyy="0.025" iyz="0.0"
               izz="0.005"/>
    </inertial>
  </link>

  <!-- ============ LEFT LEG ============ -->
  <!-- Left Hip -->
  <joint name="left_hip_joint" type="revolute">
    <parent link="base_link"/>
    <child link="left_thigh"/>
    <origin xyz="0.1 0 -0.25" rpy="0 0 0"/>
    <axis xyz="1 0 0"/>
    <limit lower="-1.57" upper="1.57" effort="30.0" velocity="2.0"/>
    <dynamics damping="0.3" friction="0.2"/>
  </joint>

  <link name="left_thigh">
    <visual>
      <origin xyz="0 0 -0.2" rpy="0 0 0"/>
      <geometry>
        <cylinder radius="0.06" length="0.4"/>
      </geometry>
      <material name="blue"/>
    </visual>
    <collision>
      <origin xyz="0 0 -0.2" rpy="0 0 0"/>
      <geometry>
        <cylinder radius="0.06" length="0.4"/>
      </geometry>
    </collision>
    <inertial>
      <mass value="3.0"/>
      <origin xyz="0 0 -0.2"/>
      <inertia ixx="0.05" ixy="0.0" ixz="0.0"
               iyy="0.05" iyz="0.0"
               izz="0.01"/>
    </inertial>
  </link>

  <!-- Left Knee -->
  <joint name="left_knee_joint" type="revolute">
    <parent link="left_thigh"/>
    <child link="left_shin"/>
    <origin xyz="0 0 -0.4" rpy="0 0 0"/>
    <axis xyz="1 0 0"/>
    <limit lower="-2.5" upper="0.0" effort="25.0" velocity="2.0"/>
    <dynamics damping="0.3" friction="0.2"/>
  </joint>

  <link name="left_shin">
    <visual>
      <origin xyz="0 0 -0.175" rpy="0 0 0"/>
      <geometry>
        <cylinder radius="0.05" length="0.35"/>
      </geometry>
      <material name="skin"/>
    </visual>
    <collision>
      <origin xyz="0 0 -0.175" rpy="0 0 0"/>
      <geometry>
        <cylinder radius="0.05" length="0.35"/>
      </geometry>
    </collision>
    <inertial>
      <mass value="2.0"/>
      <origin xyz="0 0 -0.175"/>
      <inertia ixx="0.025" ixy="0.0" ixz="0.0"
               iyy="0.025" iyz="0.0"
               izz="0.005"/>
    </inertial>
  </link>

</robot>
