<?xml version="1.0"?>
<!--
Simple Humanoid Robot URDF Model

This URDF defines a 10-joint humanoid robot with:
- 1 torso (base_link)
- 2 legs (6 joints total: hip, knee, ankle for each)
- 2 arms (4 joints total: shoulder, elbow for each)
- 1 head (neck joint)

Total: 10 revolute joints

Coordinate Frame Convention:
- X: Forward
- Y: Left
- Z: Up

Units: meters, radians

Usage:
    check_urdf simple_humanoid.urdf
    ros2 run robot_state_publisher robot_state_publisher --ros-args -p robot_description:="$(cat simple_humanoid.urdf)"
    ros2 run joint_state_publisher_gui joint_state_publisher_gui
    ros2 run rviz2 rviz2
-->
<robot name="simple_humanoid">

  <!-- ========== MATERIALS ========== -->

  <material name="blue">
    <color rgba="0.0 0.4 0.8 1.0"/>
  </material>

  <material name="red">
    <color rgba="0.8 0.2 0.0 1.0"/>
  </material>

  <material name="green">
    <color rgba="0.2 0.8 0.0 1.0"/>
  </material>

  <material name="gray">
    <color rgba="0.5 0.5 0.5 1.0"/>
  </material>

  <material name="black">
    <color rgba="0.1 0.1 0.1 1.0"/>
  </material>

  <!-- ========== BASE/TORSO ========== -->

  <link name="base_link">
    <visual>
      <geometry>
        <box size="0.3 0.4 0.6"/>
      </geometry>
      <material name="blue"/>
    </visual>
    <collision>
      <geometry>
        <box size="0.3 0.4 0.6"/>
      </geometry>
    </collision>
    <inertial>
      <mass value="10.0"/>
      <inertia ixx="1.0" ixy="0.0" ixz="0.0" iyy="1.0" iyz="0.0" izz="1.0"/>
    </inertial>
  </link>

  <!-- ========== HEAD ========== -->

  <link name="head_link">
    <visual>
      <geometry>
        <sphere radius="0.15"/>
      </geometry>
      <material name="gray"/>
    </visual>
    <collision>
      <geometry>
        <sphere radius="0.15"/>
      </geometry>
    </collision>
    <inertial>
      <mass value="2.0"/>
      <inertia ixx="0.1" ixy="0.0" ixz="0.0" iyy="0.1" iyz="0.0" izz="0.1"/>
    </inertial>
  </link>

  <joint name="neck_joint" type="revolute">
    <parent link="base_link"/>
    <child link="head_link"/>
    <origin xyz="0 0 0.45" rpy="0 0 0"/>
    <axis xyz="0 0 1"/>
    <limit lower="-1.57" upper="1.57" effort="10.0" velocity="2.0"/>
  </joint>

  <!-- ========== LEFT LEG ========== -->

  <!-- Left Hip (Thigh) -->
  <link name="left_hip_link">
    <visual>
      <origin xyz="0 0 -0.2" rpy="0 0 0"/>
      <geometry>
        <cylinder radius="0.06" length="0.4"/>
      </geometry>
      <material name="red"/>
    </visual>
    <collision>
      <origin xyz="0 0 -0.2" rpy="0 0 0"/>
      <geometry>
        <cylinder radius="0.06" length="0.4"/>
      </geometry>
    </collision>
    <inertial>
      <mass value="3.0"/>
      <inertia ixx="0.1" ixy="0.0" ixz="0.0" iyy="0.1" iyz="0.0" izz="0.05"/>
    </inertial>
  </link>

  <joint name="left_hip_joint" type="revolute">
    <parent link="base_link"/>
    <child link="left_hip_link"/>
    <origin xyz="0 0.15 -0.3" rpy="0 0 0"/>
    <axis xyz="0 1 0"/>
    <limit lower="-1.57" upper="1.57" effort="100.0" velocity="2.0"/>
  </joint>

  <!-- Left Knee (Shin) -->
  <link name="left_knee_link">
    <visual>
      <origin xyz="0 0 -0.2" rpy="0 0 0"/>
      <geometry>
        <cylinder radius="0.05" length="0.4"/>
      </geometry>
      <material name="green"/>
    </visual>
    <collision>
      <origin xyz="0 0 -0.2" rpy="0 0 0"/>
      <geometry>
        <cylinder radius="0.05" length="0.4"/>
      </geometry>
    </collision>
    <inertial>
      <mass value="2.0"/>
      <inertia ixx="0.08" ixy="0.0" ixz="0.0" iyy="0.08" iyz="0.0" izz="0.03"/>
    </inertial>
  </link>

  <joint name="left_knee_joint" type="revolute">
    <parent link="left_hip_link"/>
    <child link="left_knee_link"/>
    <origin xyz="0 0 -0.4" rpy="0 0 0"/>
    <axis xyz="0 1 0"/>
    <limit lower="0.0" upper="2.36" effort="100.0" velocity="2.0"/>
  </joint>

  <!-- Left Ankle (Foot) -->
  <link name="left_ankle_link">
    <visual>
      <origin xyz="0.05 0 0" rpy="0 0 0"/>
      <geometry>
        <box size="0.2 0.1 0.05"/>
      </geometry>
      <material name="black"/>
    </visual>
    <collision>
      <origin xyz="0.05 0 0" rpy="0 0 0"/>
      <geometry>
        <box size="0.2 0.1 0.05"/>
      </geometry>
    </collision>
    <inertial>
      <mass value="0.5"/>
      <inertia ixx="0.01" ixy="0.0" ixz="0.0" iyy="0.01" iyz="0.0" izz="0.01"/>
    </inertial>
  </link>

  <joint name="left_ankle_joint" type="revolute">
    <parent link="left_knee_link"/>
    <child link="left_ankle_link"/>
    <origin xyz="0 0 -0.4" rpy="0 0 0"/>
    <axis xyz="0 1 0"/>
    <limit lower="-0.79" upper="0.79" effort="50.0" velocity="2.0"/>
  </joint>

  <!-- ========== RIGHT LEG ========== -->

  <!-- Right Hip (Thigh) -->
  <link name="right_hip_link">
    <visual>
      <origin xyz="0 0 -0.2" rpy="0 0 0"/>
      <geometry>
        <cylinder radius="0.06" length="0.4"/>
      </geometry>
      <material name="red"/>
    </visual>
    <collision>
      <origin xyz="0 0 -0.2" rpy="0 0 0"/>
      <geometry>
        <cylinder radius="0.06" length="0.4"/>
      </geometry>
    </collision>
    <inertial>
      <mass value="3.0"/>
      <inertia ixx="0.1" ixy="0.0" ixz="0.0" iyy="0.1" iyz="0.0" izz="0.05"/>
    </inertial>
  </link>

  <joint name="right_hip_joint" type="revolute">
    <parent link="base_link"/>
    <child link="right_hip_link"/>
    <origin xyz="0 -0.15 -0.3" rpy="0 0 0"/>
    <axis xyz="0 1 0"/>
    <limit lower="-1.57" upper="1.57" effort="100.0" velocity="2.0"/>
  </joint>

  <!-- Right Knee (Shin) -->
  <link name="right_knee_link">
    <visual>
      <origin xyz="0 0 -0.2" rpy="0 0 0"/>
      <geometry>
        <cylinder radius="0.05" length="0.4"/>
      </geometry>
      <material name="green"/>
    </visual>
    <collision>
      <origin xyz="0 0 -0.2" rpy="0 0 0"/>
      <geometry>
        <cylinder radius="0.05" length="0.4"/>
      </geometry>
    </collision>
    <inertial>
      <mass value="2.0"/>
      <inertia ixx="0.08" ixy="0.0" ixz="0.0" iyy="0.08" iyz="0.0" izz="0.03"/>
    </inertial>
  </link>

  <joint name="right_knee_joint" type="revolute">
    <parent link="right_hip_link"/>
    <child link="right_knee_link"/>
    <origin xyz="0 0 -0.4" rpy="0 0 0"/>
    <axis xyz="0 1 0"/>
    <limit lower="0.0" upper="2.36" effort="100.0" velocity="2.0"/>
  </joint>

  <!-- Right Ankle (Foot) -->
  <link name="right_ankle_link">
    <visual>
      <origin xyz="0.05 0 0" rpy="0 0 0"/>
      <geometry>
        <box size="0.2 0.1 0.05"/>
      </geometry>
      <material name="black"/>
    </visual>
    <collision>
      <origin xyz="0.05 0 0" rpy="0 0 0"/>
      <geometry>
        <box size="0.2 0.1 0.05"/>
      </geometry>
    </collision>
    <inertial>
      <mass value="0.5"/>
      <inertia ixx="0.01" ixy="0.0" ixz="0.0" iyy="0.01" iyz="0.0" izz="0.01"/>
    </inertial>
  </link>

  <joint name="right_ankle_joint" type="revolute">
    <parent link="right_knee_link"/>
    <child link="right_ankle_link"/>
    <origin xyz="0 0 -0.4" rpy="0 0 0"/>
    <axis xyz="0 1 0"/>
    <limit lower="-0.79" upper="0.79" effort="50.0" velocity="2.0"/>
  </joint>

  <!-- ========== LEFT ARM ========== -->

  <!-- Left Shoulder (Upper Arm) -->
  <link name="left_shoulder_link">
    <visual>
      <origin xyz="0 0 -0.15" rpy="0 0 0"/>
      <geometry>
        <cylinder radius="0.04" length="0.3"/>
      </geometry>
      <material name="red"/>
    </visual>
    <collision>
      <origin xyz="0 0 -0.15" rpy="0 0 0"/>
      <geometry>
        <cylinder radius="0.04" length="0.3"/>
      </geometry>
    </collision>
    <inertial>
      <mass value="1.5"/>
      <inertia ixx="0.05" ixy="0.0" ixz="0.0" iyy="0.05" iyz="0.0" izz="0.02"/>
    </inertial>
  </link>

  <joint name="left_shoulder_joint" type="revolute">
    <parent link="base_link"/>
    <child link="left_shoulder_link"/>
    <origin xyz="0 0.25 0.2" rpy="0 0 0"/>
    <axis xyz="0 1 0"/>
    <limit lower="-3.14" upper="3.14" effort="50.0" velocity="2.0"/>
  </joint>

  <!-- Left Elbow (Forearm) -->
  <link name="left_elbow_link">
    <visual>
      <origin xyz="0 0 -0.15" rpy="0 0 0"/>
      <geometry>
        <cylinder radius="0.035" length="0.3"/>
      </geometry>
      <material name="green"/>
    </visual>
    <collision>
      <origin xyz="0 0 -0.15" rpy="0 0 0"/>
      <geometry>
        <cylinder radius="0.035" length="0.3"/>
      </geometry>
    </collision>
    <inertial>
      <mass value="1.0"/>
      <inertia ixx="0.03" ixy="0.0" ixz="0.0" iyy="0.03" iyz="0.0" izz="0.01"/>
    </inertial>
  </link>

  <joint name="left_elbow_joint" type="revolute">
    <parent link="left_shoulder_link"/>
    <child link="left_elbow_link"/>
    <origin xyz="0 0 -0.3" rpy="0 0 0"/>
    <axis xyz="0 1 0"/>
    <limit lower="0.0" upper="2.79" effort="30.0" velocity="2.0"/>
  </joint>

  <!-- ========== RIGHT ARM ========== -->

  <!-- Right Shoulder (Upper Arm) -->
  <link name="right_shoulder_link">
    <visual>
      <origin xyz="0 0 -0.15" rpy="0 0 0"/>
      <geometry>
        <cylinder radius="0.04" length="0.3"/>
      </geometry>
      <material name="red"/>
    </visual>
    <collision>
      <origin xyz="0 0 -0.15" rpy="0 0 0"/>
      <geometry>
        <cylinder radius="0.04" length="0.3"/>
      </geometry>
    </collision>
    <inertial>
      <mass value="1.5"/>
      <inertia ixx="0.05" ixy="0.0" ixz="0.0" iyy="0.05" iyz="0.0" izz="0.02"/>
    </inertial>
  </link>

  <joint name="right_shoulder_joint" type="revolute">
    <parent link="base_link"/>
    <child link="right_shoulder_link"/>
    <origin xyz="0 -0.25 0.2" rpy="0 0 0"/>
    <axis xyz="0 1 0"/>
    <limit lower="-3.14" upper="3.14" effort="50.0" velocity="2.0"/>
  </joint>

  <!-- Right Elbow (Forearm) -->
  <link name="right_elbow_link">
    <visual>
      <origin xyz="0 0 -0.15" rpy="0 0 0"/>
      <geometry>
        <cylinder radius="0.035" length="0.3"/>
      </geometry>
      <material name="green"/>
    </visual>
    <collision>
      <origin xyz="0 0 -0.15" rpy="0 0 0"/>
      <geometry>
        <cylinder radius="0.035" length="0.3"/>
      </geometry>
    </collision>
    <inertial>
      <mass value="1.0"/>
      <inertia ixx="0.03" ixy="0.0" ixz="0.0" iyy="0.03" iyz="0.0" izz="0.01"/>
    </inertial>
  </link>

  <joint name="right_elbow_joint" type="revolute">
    <parent link="right_shoulder_link"/>
    <child link="right_elbow_link"/>
    <origin xyz="0 0 -0.3" rpy="0 0 0"/>
    <axis xyz="0 1 0"/>
    <limit lower="0.0" upper="2.79" effort="30.0" velocity="2.0"/>
  </joint>

</robot>
